Workbook

Sheet results
A1: cell_id | B1: timestamp | C1: ecosystem | D1: A - private registry configuration | E1: B1 - package manager configuration | F1: B2 - version specifier | G1: C - pipeline operation type | H1: classification | I1: pk1_name | J1: pk1_version | K1: pk1_url | L1: pk2_name | M1: pk2_version | N1: pk2_url | O1: artifact_path | P1: git_commit | Q1: github_run_id | R1: key | S1: code | T1: C1a ≡ C1c | U1: npm B1b ≡ B1d | V1: npm B1c ≡ B1b | W1: A1a ≡ A1b
A2: npm_A1a_B1a_B2a_C1a | B2: 46272.538 | C2: nodejs | D2: A1a | E2: B1a | F2: B2a | G2: C1a | H2: private_resolved | I2: xueting-thesis-event-jianding | J2: 100 | K2: http://host.docker.internal:8081/repository/npm-group-public-first/xueting-thesis-event-jianding/-/xueting-thesis-event-jianding-1.0.0.tgz | L2: xueting-thesis-service-fasong | M2: 100 | N2: http://host.docker.internal:8081/repository/npm-group-public-first/xueting-thesis-service-fasong/-/xueting-thesis-service-fasong-1.0.0.tgz | O2: automation_process/central_automated_pipeline/artifact_download/npm_A1a_B1a_B2a_C1a | P2: 392d628e1a62a0ac3b0154c32f38e530fc871c0a | Q2: 34113888907 | R2: =C2&"|"&D2&"|"&E2&"|"&F2&"|"&G2 -> nodejs|A1a|B1a|B2a|C1a | S2: =IF(H2="malicious_resolved","M",IF(H2="private_resolved","P",IF(H2="resolution_error","E","-"))) -> P | T2: =IF(G2="C1a",IF(H2=VLOOKUP(SUBSTITUTE(A2,"_C1a","_C1c"),$A:$H,8,FALSE),"same","DIFF"),"") -> same | U2: =IF(AND(C2="nodejs",E2="B1b"),IF(H2=VLOOKUP(SUBSTITUTE(A2,"_B1b_","_B1d_"),$A:$H,8,FALSE),"same","DIFF"),"") | V2: =IF(AND(C2="nodejs",E2="B1c",H2<>"invalid_configuration"),IF(H2=VLOOKUP(SUBSTITUTE(A2,"_B1c_","_B1b_"),$A:$H,8,FALSE),"same","DIFF"),"") | W2: =IF(D2="A1a",IF(H2=VLOOKUP(SUBSTITUTE(A2,"_A1a_","_A1b_"),$A:$H,8,FALSE),"same","DIFF"),"") -> same
A3: npm_A1a_B1a_B2a_C1c | B3: 46272.539 | C3: nodejs | D3: A1a | E3: B1a | F3: B2a | G3: C1c | H3: private_resolved | I3: xueting-thesis-event-jianding | J3: 100 | K3: http://host.docker.internal:8081/repository/npm-group-public-first/xueting-thesis-event-jianding/-/xueting-thesis-event-jianding-1.0.0.tgz | L3: xueting-thesis-service-fasong | M3: 100 | N3: http://host.docker.internal:8081/repository/npm-group-public-first/xueting-thesis-service-fasong/-/xueting-thesis-service-fasong-1.0.0.tgz | O3: automation_process/central_automated_pipeline/artifact_download/npm_A1a_B1a_B2a_C1c | P3: 392d628e1a62a0ac3b0154c32f38e530fc871c0a | Q3: 34114003220 | R3: =C3&"|"&D3&"|"&E3&"|"&F3&"|"&G3 -> nodejs|A1a|B1a|B2a|C1c | S3: =IF(H3="malicious_resolved","M",IF(H3="private_resolved","P",IF(H3="resolution_error","E","-"))) -> P | T3: =IF(G3="C1a",IF(H3=VLOOKUP(SUBSTITUTE(A3,"_C1a","_C1c"),$A:$H,8,FALSE),"same","DIFF"),"") | U3: =IF(AND(C3="nodejs",E3="B1b"),IF(H3=VLOOKUP(SUBSTITUTE(A3,"_B1b_","_B1d_"),$A:$H,8,FALSE),"same","DIFF"),"") | V3: =IF(AND(C3="nodejs",E3="B1c",H3<>"invalid_configuration"),IF(H3=VLOOKUP(SUBSTITUTE(A3,"_B1c_","_B1b_"),$A:$H,8,FALSE),"same","DIFF"),"") | W3: =IF(D3="A1a",IF(H3=VLOOKUP(SUBSTITUTE(A3,"_A1a_","_A1b_"),$A:$H,8,FALSE),"same","DIFF"),"") -> same
A4: npm_A1a_B1a_B2b_C1a | B4: 46272.54 | C4: nodejs | D4: A1a | E4: B1a | F4: B2b | G4: C1a | H4: malicious_resolved | I4: xueting-thesis-event-jianding | J4: 103 | K4: http://host.docker.internal:8081/repository/npm-group-public-first/xueting-thesis-event-jianding/-/xueting-thesis-event-jianding-1.0.3.tgz | L4: xueting-thesis-service-fasong | M4: 103 | N4: http://host.docker.internal:8081/repository/npm-group-public-first/xueting-thesis-service-fasong/-/xueting-thesis-service-fasong-1.0.3.tgz | O4: automation_process/central_automated_pipeline/artifact_download/npm_A1a_B1a_B2b_C1a | P4: 392d628e1a62a0ac3b0154c32f38e530fc871c0a | Q4: 34114057763 | R4: =C4&"|"&D4&"|"&E4&"|"&F4&"|"&G4 -> nodejs|A1a|B1a|B2b|C1a | S4: =IF(H4="malicious_resolved","M",IF(H4="private_resolved","P",IF(H4="resolution_error","E","-"))) -> M | T4: =IF(G4="C1a",IF(H4=VLOOKUP(SUBSTITUTE(A4,"_C1a","_C1c"),$A:$H,8,FALSE),"same","DIFF"),"") -> same | U4: =IF(AND(C4="nodejs",E4="B1b"),IF(H4=VLOOKUP(SUBSTITUTE(A4,"_B1b_","_B1d_"),$A:$H,8,FALSE),"same","DIFF"),"") | V4: =IF(AND(C4="nodejs",E4="B1c",H4<>"invalid_configuration"),IF(H4=VLOOKUP(SUBSTITUTE(A4,"_B1c_","_B1b_"),$A:$H,8,FALSE),"same","DIFF"),"") | W4: =IF(D4="A1a",IF(H4=VLOOKUP(SUBSTITUTE(A4,"_A1a_","_A1b_"),$A:$H,8,FALSE),"same","DIFF"),"") -> same
A5: npm_A1a_B1a_B2b_C1c | B5: 46272.541 | C5: nodejs | D5: A1a | E5: B1a | F5: B2b | G5: C1c | H5: malicious_resolved | I5: xueting-thesis-event-jianding | J5: 103 | K5: http://host.docker.internal:8081/repository/npm-group-public-first/xueting-thesis-event-jianding/-/xueting-thesis-event-jianding-1.0.3.tgz | L5: xueting-thesis-service-fasong | M5: 103 | N5: http://host.docker.internal:8081/repository/npm-group-public-first/xueting-thesis-service-fasong/-/xueting-thesis-service-fasong-1.0.3.tgz | O5: automation_process/central_automated_pipeline/artifact_download/npm_A1a_B1a_B2b_C1c | P5: 392d628e1a62a0ac3b0154c32f38e530fc871c0a | Q5: 34114159819 | R5: =C5&"|"&D5&"|"&E5&"|"&F5&"|"&G5 -> nodejs|A1a|B1a|B2b|C1c | S5: =IF(H5="malicious_resolved","M",IF(H5="private_resolved","P",IF(H5="resolution_error","E","-"))) -> M | T5: =IF(G5="C1a",IF(H5=VLOOKUP(SUBSTITUTE(A5,"_C1a","_C1c"),$A:$H,8,FALSE),"same","DIFF"),"") | U5: =IF(AND(C5="nodejs",E5="B1b"),IF(H5=VLOOKUP(SUBSTITUTE(A5,"_B1b_","_B1d_"),$A:$H,8,FALSE),"same","DIFF"),"") | V5: =IF(AND(C5="nodejs",E5="B1c",H5<>"invalid_configuration"),IF(H5=VLOOKUP(SUBSTITUTE(A5,"_B1c_","_B1b_"),$A:$H,8,FALSE),"same","DIFF"),"") | W5: =IF(D5="A1a",IF(H5=VLOOKUP(SUBSTITUTE(A5,"_A1a_","_A1b_"),$A:$H,8,FALSE),"same","DIFF"),"") -> same | Y5: =COUNTIF(W2:W433,"same") -> 108
A6: npm_A1a_B1a_B2c_C1a | B6: 46272.541 | C6: nodejs | D6: A1a | E6: B1a | F6: B2c | G6: C1a | H6: malicious_resolved | I6: xueting-thesis-event-jianding | J6: 103 | K6: http://host.docker.internal:8081/repository/npm-group-public-first/xueting-thesis-event-jianding/-/xueting-thesis-event-jianding-1.0.3.tgz | L6: xueting-thesis-service-fasong | M6: 103 | N6: http://host.docker.internal:8081/repository/npm-group-public-first/xueting-thesis-service-fasong/-/xueting-thesis-service-fasong-1.0.3.tgz | O6: automation_process/central_automated_pipeline/artifact_download/npm_A1a_B1a_B2c_C1a | P6: 392d628e1a62a0ac3b0154c32f38e530fc871c0a | Q6: 34114208812 | R6: =C6&"|"&D6&"|"&E6&"|"&F6&"|"&G6 -> nodejs|A1a|B1a|B2c|C1a | S6: =IF(H6="malicious_resolved","M",IF(H6="private_resolved","P",IF(H6="resolution_error","E","-"))) -> M | T6: =IF(G6="C1a",IF(H6=VLOOKUP(SUBSTITUTE(A6,"_C1a","_C1c"),$A:$H,8,FALSE),"same","DIFF"),"") -> same | U6: =IF(AND(C6="nodejs",E6="B1b"),IF(H6=VLOOKUP(SUBSTITUTE(A6,"_B1b_","_B1d_"),$A:$H,8,FALSE),"same","DIFF"),"") | V6: =IF(AND(C6="nodejs",E6="B1c",H6<>"invalid_configuration"),IF(H6=VLOOKUP(SUBSTITUTE(A6,"_B1c_","_B1b_"),$A:$H,8,FALSE),"same","DIFF"),"") | W6: =IF(D6="A1a",IF(H6=VLOOKUP(SUBSTITUTE(A6,"_A1a_","_A1b_"),$A:$H,8,FALSE),"same","DIFF"),"") -> same | Y6: =COUNTIF(W2:W433,"DIFF") -> 0
A7: npm_A1a_B1a_B2c_C1c | B7: 46272.542 | C7: nodejs | D7: A1a | E7: B1a | F7: B2c | G7: C1c | H7: malicious_resolved | I7: xueting-thesis-event-jianding | J7: 103 | K7: http://host.docker.internal:8081/repository/npm-group-public-first/xueting-thesis-event-jianding/-/xueting-thesis-event-jianding-1.0.3.tgz | L7: xueting-thesis-service-fasong | M7: 103 | N7: http://host.docker.internal:8081/repository/npm-group-public-first/xueting-thesis-service-fasong/-/xueting-thesis-service-fasong-1.0.3.tgz | O7: automation_process/central_automated_pipeline/artifact_download/npm_A1a_B1a_B2c_C1c | P7: 392d628e1a62a0ac3b0154c32f38e530fc871c0a | Q7: 34114305648 | R7: =C7&"|"&D7&"|"&E7&"|"&F7&"|"&G7 -> nodejs|A1a|B1a|B2c|C1c | S7: =IF(H7="malicious_resolved","M",IF(H7="private_resolved","P",IF(H7="resolution_error","E","-"))) -> M | T7: =IF(G7="C1a",IF(H7=VLOOKUP(SUBSTITUTE(A7,"_C1a","_C1c"),$A:$H,8,FALSE),"same","DIFF"),"") | U7: =IF(AND(C7="nodejs",E7="B1b"),IF(H7=VLOOKUP(SUBSTITUTE(A7,"_B1b_","_B1d_"),$A:$H,8,FALSE),"same","DIFF"),"") | V7: =IF(AND(C7="nodejs",E7="B1c",H7<>"invalid_configuration"),IF(H7=VLOOKUP(SUBSTITUTE(A7,"_B1c_","_B1b_"),$A:$H,8,FALSE),"same","DIFF"),"") | W7: =IF(D7="A1a",IF(H7=VLOOKUP(SUBSTITUTE(A7,"_A1a_","_A1b_"),$A:$H,8,FALSE),"same","DIFF"),"") -> same
A8: npm_A1a_B1b_B2a_C1a | B8: 46272.542 | C8: nodejs | D8: A1a | E8: B1b | F8: B2a | G8: C1a | H8: resolution_error | O8: automation_process/central_automated_pipeline/artifact_download/npm_A1a_B1b_B2a_C1a | P8: 392d628e1a62a0ac3b0154c32f38e530fc871c0a | Q8: 34114369482 | R8: =C8&"|"&D8&"|"&E8&"|"&F8&"|"&G8 -> nodejs|A1a|B1b|B2a|C1a | S8: =IF(H8="malicious_resolved","M",IF(H8="private_resolved","P",IF(H8="resolution_error","E","-"))) -> E | T8: =IF(G8="C1a",IF(H8=VLOOKUP(SUBSTITUTE(A8,"_C1a","_C1c"),$A:$H,8,FALSE),"same","DIFF"),"") -> same | U8: =IF(AND(C8="nodejs",E8="B1b"),IF(H8=VLOOKUP(SUBSTITUTE(A8,"_B1b_","_B1d_"),$A:$H,8,FALSE),"same","DIFF"),"") -> same | V8: =IF(AND(C8="nodejs",E8="B1c",H8<>"invalid_configuration"),IF(H8=VLOOKUP(SUBSTITUTE(A8,"_B1c_","_B1b_"),$A:$H,8,FALSE),"same","DIFF"),"") | W8: =IF(D8="A1a",IF(H8=VLOOKUP(SUBSTITUTE(A8,"_A1a_","_A1b_"),$A:$H,8,FALSE),"same","DIFF"),"") -> same
A9: npm_A1a_B1b_B2a_C1c | B9: 46272.543 | C9: nodejs | D9: A1a | E9: B1b | F9: B2a | G9: C1c | H9: resolution_error | O9: automation_process/central_automated_pipeline/artifact_download/npm_A1a_B1b_B2a_C1c | P9: 392d628e1a62a0ac3b0154c32f38e530fc871c0a | Q9: 34114483207 | R9: =C9&"|"&D9&"|"&E9&"|"&F9&"|"&G9 -> nodejs|A1a|B1b|B2a|C1c | S9: =IF(H9="malicious_resolved","M",IF(H9="private_resolved","P",IF(H9="resolution_error","E","-"))) -> E | T9: =IF(G9="C1a",IF(H9=VLOOKUP(SUBSTITUTE(A9,"_C1a","_C1c"),$A:$H,8,FALSE),"same","DIFF"),"") | U9: =IF(AND(C9="nodejs",E9="B1b"),IF(H9=VLOOKUP(SUBSTITUTE(A9,"_B1b_","_B1d_"),$A:$H,8,FALSE),"same","DIFF"),"") -> same | V9: =IF(AND(C9="nodejs",E9="B1c",H9<>"invalid_configuration"),IF(H9=VLOOKUP(SUBSTITUTE(A9,"_B1c_","_B1b_"),$A:$H,8,FALSE),"same","DIFF"),"") | W9: =IF(D9="A1a",IF(H9=VLOOKUP(SUBSTITUTE(A9,"_A1a_","_A1b_"),$A:$H,8,FALSE),"same","DIFF"),"") -> same
A10: npm_A1a_B1b_B2b_C1a | B10: 46272.544 | C10: nodejs | D10: A1a | E10: B1b | F10: B2b | G10: C1a | H10: malicious_resolved | I10: xueting-thesis-event-jianding | J10: 103 | K10: https://registry.npmjs.org/xueting-thesis-event-jianding/-/xueting-thesis-event-jianding-1.0.3.tgz | L10: xueting-thesis-service-fasong | M10: 103 | N10: https://registry.npmjs.org/xueting-thesis-service-fasong/-/xueting-thesis-service-fasong-1.0.3.tgz | O10: automation_process/central_automated_pipeline/artifact_download/npm_A1a_B1b_B2b_C1a | P10: 392d628e1a62a0ac3b0154c32f38e530fc871c0a | Q10: 34114535707 | R10: =C10&"|"&D10&"|"&E10&"|"&F10&"|"&G10 -> nodejs|A1a|B1b|B2b|C1a | S10: =IF(H10="malicious_resolved","M",IF(H10="private_resolved","P",IF(H10="resolution_error","E","-"))) -> M | T10: =IF(G10="C1a",IF(H10=VLOOKUP(SUBSTITUTE(A10,"_C1a","_C1c"),$A:$H,8,FALSE),"same","DIFF"),"") -> same | U10: =IF(AND(C10="nodejs",E10="B1b"),IF(H10=VLOOKUP(SUBSTITUTE(A10,"_B1b_","_B1d_"),$A:$H,8,FALSE),"same","DIFF"),"") -> same | V10: =IF(AND(C10="nodejs",E10="B1c",H10<>"invalid_configuration"),IF(H10=VLOOKUP(SUBSTITUTE(A10,"_B1c_","_B1b_"),$A:$H,8,FALSE),"same","DIFF"),"") | W10: =IF(D10="A1a",IF(H10=VLOOKUP(SUBSTITUTE(A10,"_A1a_","_A1b_"),$A:$H,8,FALSE),"same","DIFF"),"") -> same
A11: npm_A1a_B1b_B2b_C1c | B11: 46272.544 | C11: nodejs | D11: A1a | E11: B1b | F11: B2b | G11: C1c | H11: malicious_resolved | I11: xueting-thesis-event-jianding | J11: 103 | K11: https://registry.npmjs.org/xueting-thesis-event-jianding/-/xueting-thesis-event-jianding-1.0.3.tgz | L11: xueting-thesis-service-fasong | M11: 103 | N11: https://registry.npmjs.org/xueting-thesis-service-fasong/-/xueting-thesis-service-fasong-1.0.3.tgz | O11: automation_process/central_automated_pipeline/artifact_download/npm_A1a_B1b_B2b_C1c | P11: 392d628e1a62a0ac3b0154c32f38e530fc871c0a | Q11: 34114637322 | R11: =C11&"|"&D11&"|"&E11&"|"&F11&"|"&G11 -> nodejs|A1a|B1b|B2b|C1c | S11: =IF(H11="malicious_resolved","M",IF(H11="private_resolved","P",IF(H11="resolution_error","E","-"))) -> M | T11: =IF(G11="C1a",IF(H11=VLOOKUP(SUBSTITUTE(A11,"_C1a","_C1c"),$A:$H,8,FALSE),"same","DIFF"),"") | U11: =IF(AND(C11="nodejs",E11="B1b"),IF(H11=VLOOKUP(SUBSTITUTE(A11,"_B1b_","_B1d_"),$A:$H,8,FALSE),"same","DIFF"),"") -> same | V11: =IF(AND(C11="nodejs",E11="B1c",H11<>"invalid_configuration"),IF(H11=VLOOKUP(SUBSTITUTE(A11,"_B1c_","_B1b_"),$A:$H,8,FALSE),"same","DIFF"),"") | W11: =IF(D11="A1a",IF(H11=VLOOKUP(SUBSTITUTE(A11,"_A1a_","_A1b_"),$A:$H,8,FALSE),"same","DIFF"),"") -> same
A12: npm_A1a_B1b_B2c_C1a | B12: 46272.545 | C12: nodejs | D12: A1a | E12: B1b | F12: B2c | G12: C1a | H12: malicious_resolved | I12: xueting-thesis-event-jianding | J12: 103 | K12: https://registry.npmjs.org/xueting-thesis-event-jianding/-/xueting-thesis-event-jianding-1.0.3.tgz | L12: xueting-thesis-service-fasong | M12: 103 | N12: https://registry.npmjs.org/xueting-thesis-service-fasong/-/xueting-thesis-service-fasong-1.0.3.tgz | O12: automation_process/central_automated_pipeline/artifact_download/npm_A1a_B1b_B2c_C1a | P12: 392d628e1a62a0ac3b0154c32f38e530fc871c0a | Q12: 34114690711 | R12: =C12&"|"&D12&"|"&E12&"|"&F12&"|"&G12 -> nodejs|A1a|B1b|B2c|C1a | S12: =IF(H12="malicious_resolved","M",IF(H12="private_resolved","P",IF(H12="resolution_error","E","-"))) -> M | T12: =IF(G12="C1a",IF(H12=VLOOKUP(SUBSTITUTE(A12,"_C1a","_C1c"),$A:$H,8,FALSE),"same","DIFF"),"") -> same | U12: =IF(AND(C12="nodejs",E12="B1b"),IF(H12=VLOOKUP(SUBSTITUTE(A12,"_B1b_","_B1d_"),$A:$H,8,FALSE),"same","DIFF"),"") -> same | V12: =IF(AND(C12="nodejs",E12="B1c",H12<>"invalid_configuration"),IF(H12=VLOOKUP(SUBSTITUTE(A12,"_B1c_","_B1b_"),$A:$H,8,FALSE),"same","DIFF"),"") | W12: =IF(D12="A1a",IF(H12=VLOOKUP(SUBSTITUTE(A12,"_A1a_","_A1b_"),$A:$H,8,FALSE),"same","DIFF"),"") -> same
A13: npm_A1a_B1b_B2c_C1c | B13: 46272.546 | C13: nodejs | D13: A1a | E13: B1b | F13: B2c | G13: C1c | H13: malicious_resolved | I13: xueting-thesis-event-jianding | J13: 103 | K13: https://registry.npmjs.org/xueting-thesis-event-jianding/-/xueting-thesis-event-jianding-1.0.3.tgz | L13: xueting-thesis-service-fasong | M13: 103 | N13: https://registry.npmjs.org/xueting-thesis-service-fasong/-/xueting-thesis-service-fasong-1.0.3.tgz | O13: automation_process/central_automated_pipeline/artifact_download/npm_A1a_B1b_B2c_C1c | P13: 392d628e1a62a0ac3b0154c32f38e530fc871c0a | Q13: 34114787510 | R13: =C13&"|"&D13&"|"&E13&"|"&F13&"|"&G13 -> nodejs|A1a|B1b|B2c|C1c | S13: =IF(H13="malicious_resolved","M",IF(H13="private_resolved","P",IF(H13="resolution_error","E","-"))) -> M | T13: =IF(G13="C1a",IF(H13=VLOOKUP(SUBSTITUTE(A13,"_C1a","_C1c"),$A:$H,8,FALSE),"same","DIFF"),"") | U13: =IF(AND(C13="nodejs",E13="B1b"),IF(H13=VLOOKUP(SUBSTITUTE(A13,"_B1b_","_B1d_"),$A:$H,8,FALSE),"same","DIFF"),"") -> same | V13: =IF(AND(C13="nodejs",E13="B1c",H13<>"invalid_configuration"),IF(H13=VLOOKUP(SUBSTITUTE(A13,"_B1c_","_B1b_"),$A:$H,8,FALSE),"same","DIFF"),"") | W13: =IF(D13="A1a",IF(H13=VLOOKUP(SUBSTITUTE(A13,"_A1a_","_A1b_"),$A:$H,8,FALSE),"same","DIFF"),"") -> same
A14: npm_A1a_B1c_B2a_C1a | B14: 46272.546 | C14: nodejs | D14: A1a | E14: B1c | F14: B2a | G14: C1a | H14: resolution_error | O14: automation_process/central_automated_pipeline/artifact_download/npm_A1a_B1c_B2a_C1a | P14: 392d628e1a62a0ac3b0154c32f38e530fc871c0a | Q14: 34114844504 | R14: =C14&"|"&D14&"|"&E14&"|"&F14&"|"&G14 -> nodejs|A1a|B1c|B2a|C1a | S14: =IF(H14="malicious_resolved","M",IF(H14="private_resolved","P",IF(H14="resolution_error","E","-"))) -> E | T14: =IF(G14="C1a",IF(H14=VLOOKUP(SUBSTITUTE(A14,"_C1a","_C1c"),$A:$H,8,FALSE),"same","DIFF"),"") -> same | U14: =IF(AND(C14="nodejs",E14="B1b"),IF(H14=VLOOKUP(SUBSTITUTE(A14,"_B1b_","_B1d_"),$A:$H,8,FALSE),"same","DIFF"),"") | V14: =IF(AND(C14="nodejs",E14="B1c",H14<>"invalid_configuration"),IF(H14=VLOOKUP(SUBSTITUTE(A14,"_B1c_","_B1b_"),$A:$H,8,FALSE),"same","DIFF"),"") -> same | W14: =IF(D14="A1a",IF(H14=VLOOKUP(SUBSTITUTE(A14,"_A1a_","_A1b_"),$A:$H,8,FALSE),"same","DIFF"),"") -> same
A15: npm_A1a_B1c_B2a_C1c | B15: 46272.547 | C15: nodejs | D15: A1a | E15: B1c | F15: B2a | G15: C1c | H15: resolution_error | O15: automation_process/central_automated_pipeline/artifact_download/npm_A1a_B1c_B2a_C1c | P15: 392d628e1a62a0ac3b0154c32f38e530fc871c0a | Q15: 34114952360 | R15: =C15&"|"&D15&"|"&E15&"|"&F15&"|"&G15 -> nodejs|A1a|B1c|B2a|C1c | S15: =IF(H15="malicious_resolved","M",IF(H15="private_resolved","P",IF(H15="resolution_error","E","-"))) -> E | T15: =IF(G15="C1a",IF(H15=VLOOKUP(SUBSTITUTE(A15,"_C1a","_C1c"),$A:$H,8,FALSE),"same","DIFF"),"") | U15: =IF(AND(C15="nodejs",E15="B1b"),IF(H15=VLOOKUP(SUBSTITUTE(A15,"_B1b_","_B1d_"),$A:$H,8,FALSE),"same","DIFF"),"") | V15: =IF(AND(C15="nodejs",E15="B1c",H15<>"invalid_configuration"),IF(H15=VLOOKUP(SUBSTITUTE(A15,"_B1c_","_B1b_"),$A:$H,8,FALSE),"same","DIFF"),"") -> same | W15: =IF(D15="A1a",IF(H15=VLOOKUP(SUBSTITUTE(A15,"_A1a_","_A1b_"),$A:$H,8,FALSE),"same","DIFF"),"") -> same
A16: npm_A1a_B1c_B2b_C1a | B16: 46272.547 | C16: nodejs | D16: A1a | E16: B1c | F16: B2b | G16: C1a | H16: malicious_resolved | I16: xueting-thesis-event-jianding | J16: 103 | K16: http://host.docker.internal:8081/repository/npm-public-proxy/xueting-thesis-event-jianding/-/xueting-thesis-event-jianding-1.0.3.tgz | L16: xueting-thesis-service-fasong | M16: 103 | N16: http://host.docker.internal:8081/repository/npm-public-proxy/xueting-thesis-service-fasong/-/xueting-thesis-service-fasong-1.0.3.tgz | O16: automation_process/central_automated_pipeline/artifact_download/npm_A1a_B1c_B2b_C1a | P16: 392d628e1a62a0ac3b0154c32f38e530fc871c0a | Q16: 34115004820 | R16: =C16&"|"&D16&"|"&E16&"|"&F16&"|"&G16 -> nodejs|A1a|B1c|B2b|C1a | S16: =IF(H16="malicious_resolved","M",IF(H16="private_resolved","P",IF(H16="resolution_error","E","-"))) -> M | T16: =IF(G16="C1a",IF(H16=VLOOKUP(SUBSTITUTE(A16,"_C1a","_C1c"),$A:$H,8,FALSE),"same","DIFF"),"") -> same | U16: =IF(AND(C16="nodejs",E16="B1b"),IF(H16=VLOOKUP(SUBSTITUTE(A16,"_B1b_","_B1d_"),$A:$H,8,FALSE),"same","DIFF"),"") | V16: =IF(AND(C16="nodejs",E16="B1c",H16<>"invalid_configuration"),IF(H16=VLOOKUP(SUBSTITUTE(A16,"_B1c_","_B1b_"),$A:$H,8,FALSE),"same","DIFF"),"") -> same | W16: =IF(D16="A1a",IF(H16=VLOOKUP(SUBSTITUTE(A16,"_A1a_","_A1b_"),$A:$H,8,FALSE),"same","DIFF"),"") -> same
A17: npm_A1a_B1c_B2b_C1c | B17: 46272.548 | C17: nodejs | D17: A1a | E17: B1c | F17: B2b | G17: C1c | H17: malicious_resolved | I17: xueting-thesis-event-jianding | J17: 103 | K17: http://host.docker.internal:8081/repository/npm-public-proxy/xueting-thesis-event-jianding/-/xueting-thesis-event-jianding-1.0.3.tgz | L17: xueting-thesis-service-fasong | M17: 103 | N17: http://host.docker.internal:8081/repository/npm-public-proxy/xueting-thesis-service-fasong/-/xueting-thesis-service-fasong-1.0.3.tgz | O17: automation_process/central_automated_pipeline/artifact_download/npm_A1a_B1c_B2b_C1c | P17: 392d628e1a62a0ac3b0154c32f38e530fc871c0a | Q17: 34115104720 | R17: =C17&"|"&D17&"|"&E17&"|"&F17&"|"&G17 -> nodejs|A1a|B1c|B2b|C1c | S17: =IF(H17="malicious_resolved","M",IF(H17="private_resolved","P",IF(H17="resolution_error","E","-"))) -> M | T17: =IF(G17="C1a",IF(H17=VLOOKUP(SUBSTITUTE(A17,"_C1a","_C1c"),$A:$H,8,FALSE),"same","DIFF"),"") | U17: =IF(AND(C17="nodejs",E17="B1b"),IF(H17=VLOOKUP(SUBSTITUTE(A17,"_B1b_","_B1d_"),$A:$H,8,FALSE),"same","DIFF"),"") | V17: =IF(AND(C17="nodejs",E17="B1c",H17<>"invalid_configuration"),IF(H17=VLOOKUP(SUBSTITUTE(A17,"_B1c_","_B1b_"),$A:$H,8,FALSE),"same","DIFF"),"") -> same | W17: =IF(D17="A1a",IF(H17=VLOOKUP(SUBSTITUTE(A17,"_A1a_","_A1b_"),$A:$H,8,FALSE),"same","DIFF"),"") -> same
A18: npm_A1a_B1c_B2c_C1a | B18: 46272.549 | C18: nodejs | D18: A1a | E18: B1c | F18: B2c | G18: C1a | H18: malicious_resolved | I18: xueting-thesis-event-jianding | J18: 103 | K18: http://host.docker.internal:8081/repository/npm-public-proxy/xueting-thesis-event-jianding/-/xueting-thesis-event-jianding-1.0.3.tgz | L18: xueting-thesis-service-fasong | M18: 103 | N18: http://host.docker.internal:8081/repository/npm-public-proxy/xueting-thesis-service-fasong/-/xueting-thesis-service-fasong-1.0.3.tgz | O18: automation_process/central_automated_pipeline/artifact_download/npm_A1a_B1c_B2c_C1a | P18: 392d628e1a62a0ac3b0154c32f38e530fc871c0a | Q18: 34115162489 | R18: =C18&"|"&D18&"|"&E18&"|"&F18&"|"&G18 -> nodejs|A1a|B1c|B2c|C1a | S18: =IF(H18="malicious_resolved","M",IF(H18="private_resolved","P",IF(H18="resolution_error","E","-"))) -> M | T18: =IF(G18="C1a",IF(H18=VLOOKUP(SUBSTITUTE(A18,"_C1a","_C1c"),$A:$H,8,FALSE),"same","DIFF"),"") -> same | U18: =IF(AND(C18="nodejs",E18="B1b"),IF(H18=VLOOKUP(SUBSTITUTE(A18,"_B1b_","_B1d_"),$A:$H,8,FALSE),"same","DIFF"),"") | V18: =IF(AND(C18="nodejs",E18="B1c",H18<>"invalid_configuration"),IF(H18=VLOOKUP(SUBSTITUTE(A18,"_B1c_","_B1b_"),$A:$H,8,FALSE),"same","DIFF"),"") -> same | W18: =IF(D18="A1a",IF(H18=VLOOKUP(SUBSTITUTE(A18,"_A1a_","_A1b_"),$A:$H,8,FALSE),"same","DIFF"),"") -> same
A19: npm_A1a_B1c_B2c_C1c | B19: 46272.549 | C19: nodejs | D19: A1a | E19: B1c | F19: B2c | G19: C1c | H19: malicious_resolved | I19: xueting-thesis-event-jianding | J19: 103 | K19: http://host.docker.internal:8081/repository/npm-public-proxy/xueting-thesis-event-jianding/-/xueting-thesis-event-jianding-1.0.3.tgz | L19: xueting-thesis-service-fasong | M19: 103 | N19: http://host.docker.internal:8081/repository/npm-public-proxy/xueting-thesis-service-fasong/-/xueting-thesis-service-fasong-1.0.3.tgz | O19: automation_process/central_automated_pipeline/artifact_download/npm_A1a_B1c_B2c_C1c | P19: 392d628e1a62a0ac3b0154c32f38e530fc871c0a | Q19: 34115272384 | R19: =C19&"|"&D19&"|"&E19&"|"&F19&"|"&G19 -> nodejs|A1a|B1c|B2c|C1c | S19: =IF(H19="malicious_resolved","M",IF(H19="private_resolved","P",IF(H19="resolution_error","E","-"))) -> M | T19: =IF(G19="C1a",IF(H19=VLOOKUP(SUBSTITUTE(A19,"_C1a","_C1c"),$A:$H,8,FALSE),"same","DIFF"),"") | U19: =IF(AND(C19="nodejs",E19="B1b"),IF(H19=VLOOKUP(SUBSTITUTE(A19,"_B1b_","_B1d_"),$A:$H,8,FALSE),"same","DIFF"),"") | V19: =IF(AND(C19="nodejs",E19="B1c",H19<>"invalid_configuration"),IF(H19=VLOOKUP(SUBSTITUTE(A19,"_B1c_","_B1b_"),$A:$H,8,FALSE),"same","DIFF"),"") -> same | W19: =IF(D19="A1a",IF(H19=VLOOKUP(SUBSTITUTE(A19,"_A1a_","_A1b_"),$A:$H,8,FALSE),"same","DIFF"),"") -> same
A20: npm_A1a_B1d_B2a_C1a | B20: 46272.55 | C20: nodejs | D20: A1a | E20: B1d | F20: B2a | G20: C1a | H20: resolution_error | O20: automation_process/central_automated_pipeline/artifact_download/npm_A1a_B1d_B2a_C1a | P20: 392d628e1a62a0ac3b0154c32f38e530fc871c0a | Q20: 34115330065 | R20: =C20&"|"&D20&"|"&E20&"|"&F20&"|"&G20 -> nodejs|A1a|B1d|B2a|C1a | S20: =IF(H20="malicious_resolved","M",IF(H20="private_resolved","P",IF(H20="resolution_error","E","-"))) -> E | T20: =IF(G20="C1a",IF(H20=VLOOKUP(SUBSTITUTE(A20,"_C1a","_C1c"),$A:$H,8,FALSE),"same","DIFF"),"") -> same | U20: =IF(AND(C20="nodejs",E20="B1b"),IF(H20=VLOOKUP(SUBSTITUTE(A20,"_B1b_","_B1d_"),$A:$H,8,FALSE),"same","DIFF"),"") | V20: =IF(AND(C20="nodejs",E20="B1c",H20<>"invalid_configuration"),IF(H20=VLOOKUP(SUBSTITUTE(A20,"_B1c_","_B1b_"),$A:$H,8,FALSE),"same","DIFF"),"") | W20: =IF(D20="A1a",IF(H20=VLOOKUP(SUBSTITUTE(A20,"_A1a_","_A1b_"),$A:$H,8,FALSE),"same","DIFF"),"") -> same
A21: npm_A1a_B1d_B2a_C1c | B21: 46272.551 | C21: nodejs | D21: A1a | E21: B1d | F21: B2a | G21: C1c | H21: resolution_error | O21: automation_process/central_automated_pipeline/artifact_download/npm_A1a_B1d_B2a_C1c | P21: 392d628e1a62a0ac3b0154c32f38e530fc871c0a | Q21: 34115441545 | R21: =C21&"|"&D21&"|"&E21&"|"&F21&"|"&G21 -> nodejs|A1a|B1d|B2a|C1c | S21: =IF(H21="malicious_resolved","M",IF(H21="private_resolved","P",IF(H21="resolution_error","E","-"))) -> E | T21: =IF(G21="C1a",IF(H21=VLOOKUP(SUBSTITUTE(A21,"_C1a","_C1c"),$A:$H,8,FALSE),"same","DIFF"),"") | U21: =IF(AND(C21="nodejs",E21="B1b"),IF(H21=VLOOKUP(SUBSTITUTE(A21,"_B1b_","_B1d_"),$A:$H,8,FALSE),"same","DIFF"),"") | V21: =IF(AND(C21="nodejs",E21="B1c",H21<>"invalid_configuration"),IF(H21=VLOOKUP(SUBSTITUTE(A21,"_B1c_","_B1b_"),$A:$H,8,FALSE),"same","DIFF"),"") | W21: =IF(D21="A1a",IF(H21=VLOOKUP(SUBSTITUTE(A21,"_A1a_","_A1b_"),$A:$H,8,FALSE),"same","DIFF"),"") -> same
A22: npm_A1a_B1d_B2b_C1a | B22: 46272.551 | C22: nodejs | D22: A1a | E22: B1d | F22: B2b | G22: C1a | H22: malicious_resolved | I22: xueting-thesis-event-jianding | J22: 103 | K22: https://registry.npmjs.org/xueting-thesis-event-jianding/-/xueting-thesis-event-jianding-1.0.3.tgz | L22: xueting-thesis-service-fasong | M22: 103 | N22: https://registry.npmjs.org/xueting-thesis-service-fasong/-/xueting-thesis-service-fasong-1.0.3.tgz | O22: automation_process/central_automated_pipeline/artifact_download/npm_A1a_B1d_B2b_C1a | P22: 392d628e1a62a0ac3b0154c32f38e530fc871c0a | Q22: 34115499907 | R22: =C22&"|"&D22&"|"&E22&"|"&F22&"|"&G22 -> nodejs|A1a|B1d|B2b|C1a | S22: =IF(H22="malicious_resolved","M",IF(H22="private_resolved","P",IF(H22="resolution_error","E","-"))) -> M | T22: =IF(G22="C1a",IF(H22=VLOOKUP(SUBSTITUTE(A22,"_C1a","_C1c"),$A:$H,8,FALSE),"same","DIFF"),"") -> same | U22: =IF(AND(C22="nodejs",E22="B1b"),IF(H22=VLOOKUP(SUBSTITUTE(A22,"_B1b_","_B1d_"),$A:$H,8,FALSE),"same","DIFF"),"") | V22: =IF(AND(C22="nodejs",E22="B1c",H22<>"invalid_configuration"),IF(H22=VLOOKUP(SUBSTITUTE(A22,"_B1c_","_B1b_"),$A:$H,8,FALSE),"same","DIFF"),"") | W22: =IF(D22="A1a",IF(H22=VLOOKUP(SUBSTITUTE(A22,"_A1a_","_A1b_"),$A:$H,8,FALSE),"same","DIFF"),"") -> same
A23: npm_A1a_B1d_B2b_C1c | B23: 46272.552 | C23: nodejs | D23: A1a | E23: B1d | F23: B2b | G23: C1c | H23: malicious_resolved | I23: xueting-thesis-event-jianding | J23: 103 | K23: https://registry.npmjs.org/xueting-thesis-event-jianding/-/xueting-thesis-event-jianding-1.0.3.tgz | L23: xueting-thesis-service-fasong | M23: 103 | N23: https://registry.npmjs.org/xueting-thesis-service-fasong/-/xueting-thesis-service-fasong-1.0.3.tgz | O23: automation_process/central_automated_pipeline/artifact_download/npm_A1a_B1d_B2b_C1c | P23: 392d628e1a62a0ac3b0154c32f38e530fc871c0a | Q23: 34115617847 | R23: =C23&"|"&D23&"|"&E23&"|"&F23&"|"&G23 -> nodejs|A1a|B1d|B2b|C1c | S23: =IF(H23="malicious_resolved","M",IF(H23="private_resolved","P",IF(H23="resolution_error","E","-"))) -> M | T23: =IF(G23="C1a",IF(H23=VLOOKUP(SUBSTITUTE(A23,"_C1a","_C1c"),$A:$H,8,FALSE),"same","DIFF"),"") | U23: =IF(AND(C23="nodejs",E23="B1b"),IF(H23=VLOOKUP(SUBSTITUTE(A23,"_B1b_","_B1d_"),$A:$H,8,FALSE),"same","DIFF"),"") | V23: =IF(AND(C23="nodejs",E23="B1c",H23<>"invalid_configuration"),IF(H23=VLOOKUP(SUBSTITUTE(A23,"_B1c_","_B1b_"),$A:$H,8,FALSE),"same","DIFF"),"") | W23: =IF(D23="A1a",IF(H23=VLOOKUP(SUBSTITUTE(A23,"_A1a_","_A1b_"),$A:$H,8,FALSE),"same","DIFF"),"") -> same
A24: npm_A1a_B1d_B2c_C1a | B24: 46272.553 | C24: nodejs | D24: A1a | E24: B1d | F24: B2c | G24: C1a | H24: malicious_resolved | I24: xueting-thesis-event-jianding | J24: 103 | K24: https://registry.npmjs.org/xueting-thesis-event-jianding/-/xueting-thesis-event-jianding-1.0.3.tgz | L24: xueting-thesis-service-fasong | M24: 103 | N24: https://registry.npmjs.org/xueting-thesis-service-fasong/-/xueting-thesis-service-fasong-1.0.3.tgz | O24: automation_process/central_automated_pipeline/artifact_download/npm_A1a_B1d_B2c_C1a | P24: 392d628e1a62a0ac3b0154c32f38e530fc871c0a | Q24: 34115678801 | R24: =C24&"|"&D24&"|"&E24&"|"&F24&"|"&G24 -> nodejs|A1a|B1d|B2c|C1a | S24: =IF(H24="malicious_resolved","M",IF(H24="private_resolved","P",IF(H24="resolution_error","E","-"))) -> M | T24: =IF(G24="C1a",IF(H24=VLOOKUP(SUBSTITUTE(A24,"_C1a","_C1c"),$A:$H,8,FALSE),"same","DIFF"),"") -> same | U24: =IF(AND(C24="nodejs",E24="B1b"),IF(H24=VLOOKUP(SUBSTITUTE(A24,"_B1b_","_B1d_"),$A:$H,8,FALSE),"same","DIFF"),"") | V24: =IF(AND(C24="nodejs",E24="B1c",H24<>"invalid_configuration"),IF(H24=VLOOKUP(SUBSTITUTE(A24,"_B1c_","_B1b_"),$A:$H,8,FALSE),"same","DIFF"),"") | W24: =IF(D24="A1a",IF(H24=VLOOKUP(SUBSTITUTE(A24,"_A1a_","_A1b_"),$A:$H,8,FALSE),"same","DIFF"),"") -> same
A25: npm_A1a_B1d_B2c_C1c | B25: 46272.553 | C25: nodejs | D25: A1a | E25: B1d | F25: B2c | G25: C1c | H25: malicious_resolved | I25: xueting-thesis-event-jianding | J25: 103 | K25: https://registry.npmjs.org/xueting-thesis-event-jianding/-/xueting-thesis-event-jianding-1.0.3.tgz | L25: xueting-thesis-service-fasong | M25: 103 | N25: https://registry.npmjs.org/xueting-thesis-service-fasong/-/xueting-thesis-service-fasong-1.0.3.tgz | O25: automation_process/central_automated_pipeline/artifact_download/npm_A1a_B1d_B2c_C1c | P25: 392d628e1a62a0ac3b0154c32f38e530fc871c0a | Q25: 34115784848 | R25: =C25&"|"&D25&"|"&E25&"|"&F25&"|"&G25 -> nodejs|A1a|B1d|B2c|C1c | S25: =IF(H25="malicious_resolved","M",IF(H25="private_resolved","P",IF(H25="resolution_error","E","-"))) -> M | T25: =IF(G25="C1a",IF(H25=VLOOKUP(SUBSTITUTE(A25,"_C1a","_C1c"),$A:$H,8,FALSE),"same","DIFF"),"") | U25: =IF(AND(C25="nodejs",E25="B1b"),IF(H25=VLOOKUP(SUBSTITUTE(A25,"_B1b_","_B1d_"),$A:$H,8,FALSE),"same","DIFF"),"") | V25: =IF(AND(C25="nodejs",E25="B1c",H25<>"invalid_configuration"),IF(H25=VLOOKUP(SUBSTITUTE(A25,"_B1c_","_B1b_"),$A:$H,8,FALSE),"same","DIFF"),"") | W25: =IF(D25="A1a",IF(H25=VLOOKUP(SUBSTITUTE(A25,"_A1a_","_A1b_"),$A:$H,8,FALSE),"same","DIFF"),"") -> same
A26: npm_A1b_B1a_B2a_C1a | B26: 46272.554 | C26: nodejs | D26: A1b | E26: B1a | F26: B2a | G26: C1a | H26: private_resolved | I26: xueting-thesis-event-jianding | J26: 100 | K26: http://host.docker.internal:8081/repository/npm-group-private-first/xueting-thesis-event-jianding/-/xueting-thesis-event-jianding-1.0.0.tgz | L26: xueting-thesis-service-fasong | M26: 100 | N26: http://host.docker.internal:8081/repository/npm-group-private-first/xueting-thesis-service-fasong/-/xueting-thesis-service-fasong-1.0.0.tgz | O26: automation_process/central_automated_pipeline/artifact_download/npm_A1b_B1a_B2a_C1a | P26: 392d628e1a62a0ac3b0154c32f38e530fc871c0a | Q26: 34115837590 | R26: =C26&"|"&D26&"|"&E26&"|"&F26&"|"&G26 -> nodejs|A1b|B1a|B2a|C1a | S26: =IF(H26="malicious_resolved","M",IF(H26="private_resolved","P",IF(H26="resolution_error","E","-"))) -> P | T26: =IF(G26="C1a",IF(H26=VLOOKUP(SUBSTITUTE(A26,"_C1a","_C1c"),$A:$H,8,FALSE),"same","DIFF"),"") -> same | U26: =IF(AND(C26="nodejs",E26="B1b"),IF(H26=VLOOKUP(SUBSTITUTE(A26,"_B1b_","_B1d_"),$A:$H,8,FALSE),"same","DIFF"),"") | V26: =IF(AND(C26="nodejs",E26="B1c",H26<>"invalid_configuration"),IF(H26=VLOOKUP(SUBSTITUTE(A26,"_B1c_","_B1b_"),$A:$H,8,FALSE),"same","DIFF"),"") | W26: =IF(D26="A1a",IF(H26=VLOOKUP(SUBSTITUTE(A26,"_A1a_","_A1b_"),$A:$H,8,FALSE),"same","DIFF"),"")
A27: npm_A1b_B1a_B2a_C1c | B27: 46272.555 | C27: nodejs | D27: A1b | E27: B1a | F27: B2a | G27: C1c | H27: private_resolved | I27: xueting-thesis-event-jianding | J27: 100 | K27: http://host.docker.internal:8081/repository/npm-group-private-first/xueting-thesis-event-jianding/-/xueting-thesis-event-jianding-1.0.0.tgz | L27: xueting-thesis-service-fasong | M27: 100 | N27: http://host.docker.internal:8081/repository/npm-group-private-first/xueting-thesis-service-fasong/-/xueting-thesis-service-fasong-1.0.0.tgz | O27: automation_process/central_automated_pipeline/artifact_download/npm_A1b_B1a_B2a_C1c | P27: 392d628e1a62a0ac3b0154c32f38e530fc871c0a | Q27: 34115935529 | R27: =C27&"|"&D27&"|"&E27&"|"&F27&"|"&G27 -> nodejs|A1b|B1a|B2a|C1c | S27: =IF(H27="malicious_resolved","M",IF(H27="private_resolved","P",IF(H27="resolution_error","E","-"))) -> P | T27: =IF(G27="C1a",IF(H27=VLOOKUP(SUBSTITUTE(A27,"_C1a","_C1c"),$A:$H,8,FALSE),"same","DIFF"),"") | U27: =IF(AND(C27="nodejs",E27="B1b"),IF(H27=VLOOKUP(SUBSTITUTE(A27,"_B1b_","_B1d_"),$A:$H,8,FALSE),"same","DIFF"),"") | V27: =IF(AND(C27="nodejs",E27="B1c",H27<>"invalid_configuration"),IF(H27=VLOOKUP(SUBSTITUTE(A27,"_B1c_","_B1b_"),$A:$H,8,FALSE),"same","DIFF"),"") | W27: =IF(D27="A1a",IF(H27=VLOOKUP(SUBSTITUTE(A27,"_A1a_","_A1b_"),$A:$H,8,FALSE),"same","DIFF"),"")
A28: npm_A1b_B1a_B2b_C1a | B28: 46272.555 | C28: nodejs | D28: A1b | E28: B1a | F28: B2b | G28: C1a | H28: malicious_resolved | I28: xueting-thesis-event-jianding | J28: 103 | K28: http://host.docker.internal:8081/repository/npm-group-private-first/xueting-thesis-event-jianding/-/xueting-thesis-event-jianding-1.0.3.tgz | L28: xueting-thesis-service-fasong | M28: 103 | N28: http://host.docker.internal:8081/repository/npm-group-private-first/xueting-thesis-service-fasong/-/xueting-thesis-service-fasong-1.0.3.tgz | O28: automation_process/central_automated_pipeline/artifact_download/npm_A1b_B1a_B2b_C1a | P28: 392d628e1a62a0ac3b0154c32f38e530fc871c0a | Q28: 34115994072 | R28: =C28&"|"&D28&"|"&E28&"|"&F28&"|"&G28 -> nodejs|A1b|B1a|B2b|C1a | S28: =IF(H28="malicious_resolved","M",IF(H28="private_resolved","P",IF(H28="resolution_error","E","-"))) -> M | T28: =IF(G28="C1a",IF(H28=VLOOKUP(SUBSTITUTE(A28,"_C1a","_C1c"),$A:$H,8,FALSE),"same","DIFF"),"") -> same | U28: =IF(AND(C28="nodejs",E28="B1b"),IF(H28=VLOOKUP(SUBSTITUTE(A28,"_B1b_","_B1d_"),$A:$H,8,FALSE),"same","DIFF"),"") | V28: =IF(AND(C28="nodejs",E28="B1c",H28<>"invalid_configuration"),IF(H28=VLOOKUP(SUBSTITUTE(A28,"_B1c_","_B1b_"),$A:$H,8,FALSE),"same","DIFF"),"") | W28: =IF(D28="A1a",IF(H28=VLOOKUP(SUBSTITUTE(A28,"_A1a_","_A1b_"),$A:$H,8,FALSE),"same","DIFF"),"")
A29: npm_A1b_B1a_B2b_C1c | B29: 46272.556 | C29: nodejs | D29: A1b | E29: B1a | F29: B2b | G29: C1c | H29: malicious_resolved | I29: xueting-thesis-event-jianding | J29: 103 | K29: http://host.docker.internal:8081/repository/npm-group-private-first/xueting-thesis-event-jianding/-/xueting-thesis-event-jianding-1.0.3.tgz | L29: xueting-thesis-service-fasong | M29: 103 | N29: http://host.docker.internal:8081/repository/npm-group-private-first/xueting-thesis-service-fasong/-/xueting-thesis-service-fasong-1.0.3.tgz | O29: automation_process/central_automated_pipeline/artifact_download/npm_A1b_B1a_B2b_C1c | P29: 392d628e1a62a0ac3b0154c32f38e530fc871c0a | Q29: 34116096214 | R29: =C29&"|"&D29&"|"&E29&"|"&F29&"|"&G29 -> nodejs|A1b|B1a|B2b|C1c | S29: =IF(H29="malicious_resolved","M",IF(H29="private_resolved","P",IF(H29="resolution_error","E","-"))) -> M | T29: =IF(G29="C1a",IF(H29=VLOOKUP(SUBSTITUTE(A29,"_C1a","_C1c"),$A:$H,8,FALSE),"same","DIFF"),"") | U29: =IF(AND(C29="nodejs",E29="B1b"),IF(H29=VLOOKUP(SUBSTITUTE(A29,"_B1b_","_B1d_"),$A:$H,8,FALSE),"same","DIFF"),"") | V29: =IF(AND(C29="nodejs",E29="B1c",H29<>"invalid_configuration"),IF(H29=VLOOKUP(SUBSTITUTE(A29,"_B1c_","_B1b_"),$A:$H,8,FALSE),"same","DIFF"),"") | W29: =IF(D29="A1a",IF(H29=VLOOKUP(SUBSTITUTE(A29,"_A1a_","_A1b_"),$A:$H,8,FALSE),"same","DIFF"),"")
A30: npm_A1b_B1a_B2c_C1a | B30: 46272.556 | C30: nodejs | D30: A1b | E30: B1a | F30: B2c | G30: C1a | H30: malicious_resolved | I30: xueting-thesis-event-jianding | J30: 103 | K30: http://host.docker.internal:8081/repository/npm-group-private-first/xueting-thesis-event-jianding/-/xueting-thesis-event-jianding-1.0.3.tgz | L30: xueting-thesis-service-fasong | M30: 103 | N30: http://host.docker.internal:8081/repository/npm-group-private-first/xueting-thesis-service-fasong/-/xueting-thesis-service-fasong-1.0.3.tgz | O30: automation_process/central_automated_pipeline/artifact_download/npm_A1b_B1a_B2c_C1a | P30: 392d628e1a62a0ac3b0154c32f38e530fc871c0a | Q30: 34116151303 | R30: =C30&"|"&D30&"|"&E30&"|"&F30&"|"&G30 -> nodejs|A1b|B1a|B2c|C1a | S30: =IF(H30="malicious_resolved","M",IF(H30="private_resolved","P",IF(H30="resolution_error","E","-"))) -> M | T30: =IF(G30="C1a",IF(H30=VLOOKUP(SUBSTITUTE(A30,"_C1a","_C1c"),$A:$H,8,FALSE),"same","DIFF"),"") -> same | U30: =IF(AND(C30="nodejs",E30="B1b"),IF(H30=VLOOKUP(SUBSTITUTE(A30,"_B1b_","_B1d_"),$A:$H,8,FALSE),"same","DIFF"),"") | V30: =IF(AND(C30="nodejs",E30="B1c",H30<>"invalid_configuration"),IF(H30=VLOOKUP(SUBSTITUTE(A30,"_B1c_","_B1b_"),$A:$H,8,FALSE),"same","DIFF"),"") | W30: =IF(D30="A1a",IF(H30=VLOOKUP(SUBSTITUTE(A30,"_A1a_","_A1b_"),$A:$H,8,FALSE),"same","DIFF"),"")
A31: npm_A1b_B1a_B2c_C1c | B31: 46272.557 | C31: nodejs | D31: A1b | E31: B1a | F31: B2c | G31: C1c | H31: malicious_resolved | I31: xueting-thesis-event-jianding | J31: 103 | K31: http://host.docker.internal:8081/repository/npm-group-private-first/xueting-thesis-event-jianding/-/xueting-thesis-event-jianding-1.0.3.tgz | L31: xueting-thesis-service-fasong | M31: 103 | N31: http://host.docker.internal:8081/repository/npm-group-private-first/xueting-thesis-service-fasong/-/xueting-thesis-service-fasong-1.0.3.tgz | O31: automation_process/central_automated_pipeline/artifact_download/npm_A1b_B1a_B2c_C1c | P31: 392d628e1a62a0ac3b0154c32f38e530fc871c0a | Q31: 34116253591 | R31: =C31&"|"&D31&"|"&E31&"|"&F31&"|"&G31 -> nodejs|A1b|B1a|B2c|C1c | S31: =IF(H31="malicious_resolved","M",IF(H31="private_resolved","P",IF(H31="resolution_error","E","-"))) -> M | T31: =IF(G31="C1a",IF(H31=VLOOKUP(SUBSTITUTE(A31,"_C1a","_C1c"),$A:$H,8,FALSE),"same","DIFF"),"") | U31: =IF(AND(C31="nodejs",E31="B1b"),IF(H31=VLOOKUP(SUBSTITUTE(A31,"_B1b_","_B1d_"),$A:$H,8,FALSE),"same","DIFF"),"") | V31: =IF(AND(C31="nodejs",E31="B1c",H31<>"invalid_configuration"),IF(H31=VLOOKUP(SUBSTITUTE(A31,"_B1c_","_B1b_"),$A:$H,8,FALSE),"same","DIFF"),"") | W31: =IF(D31="A1a",IF(H31=VLOOKUP(SUBSTITUTE(A31,"_A1a_","_A1b_"),$A:$H,8,FALSE),"same","DIFF"),"")
A32: npm_A1b_B1b_B2a_C1a | B32: 46272.558 | C32: nodejs | D32: A1b | E32: B1b | F32: B2a | G32: C1a | H32: resolution_error | O32: automation_process/central_automated_pipeline/artifact_download/npm_A1b_B1b_B2a_C1a | P32: 392d628e1a62a0ac3b0154c32f38e530fc871c0a | Q32: 34116308952 | R32: =C32&"|"&D32&"|"&E32&"|"&F32&"|"&G32 -> nodejs|A1b|B1b|B2a|C1a | S32: =IF(H32="malicious_resolved","M",IF(H32="private_resolved","P",IF(H32="resolution_error","E","-"))) -> E | T32: =IF(G32="C1a",IF(H32=VLOOKUP(SUBSTITUTE(A32,"_C1a","_C1c"),$A:$H,8,FALSE),"same","DIFF"),"") -> same | U32: =IF(AND(C32="nodejs",E32="B1b"),IF(H32=VLOOKUP(SUBSTITUTE(A32,"_B1b_","_B1d_"),$A:$H,8,FALSE),"same","DIFF"),"") -> same | V32: =IF(AND(C32="nodejs",E32="B1c",H32<>"invalid_configuration"),IF(H32=VLOOKUP(SUBSTITUTE(A32,"_B1c_","_B1b_"),$A:$H,8,FALSE),"same","DIFF"),"") | W32: =IF(D32="A1a",IF(H32=VLOOKUP(SUBSTITUTE(A32,"_A1a_","_A1b_"),$A:$H,8,FALSE),"same","DIFF"),"")
A33: npm_A1b_B1b_B2a_C1c | B33: 46272.559 | C33: nodejs | D33: A1b | E33: B1b | F33: B2a | G33: C1c | H33: resolution_error | O33: automation_process/central_automated_pipeline/artifact_download/npm_A1b_B1b_B2a_C1c | P33: 392d628e1a62a0ac3b0154c32f38e530fc871c0a | Q33: 34116407149 | R33: =C33&"|"&D33&"|"&E33&"|"&F33&"|"&G33 -> nodejs|A1b|B1b|B2a|C1c | S33: =IF(H33="malicious_resolved","M",IF(H33="private_resolved","P",IF(H33="resolution_error","E","-"))) -> E | T33: =IF(G33="C1a",IF(H33=VLOOKUP(SUBSTITUTE(A33,"_C1a","_C1c"),$A:$H,8,FALSE),"same","DIFF"),"") | U33: =IF(AND(C33="nodejs",E33="B1b"),IF(H33=VLOOKUP(SUBSTITUTE(A33,"_B1b_","_B1d_"),$A:$H,8,FALSE),"same","DIFF"),"") -> same | V33: =IF(AND(C33="nodejs",E33="B1c",H33<>"invalid_configuration"),IF(H33=VLOOKUP(SUBSTITUTE(A33,"_B1c_","_B1b_"),$A:$H,8,FALSE),"same","DIFF"),"") | W33: =IF(D33="A1a",IF(H33=VLOOKUP(SUBSTITUTE(A33,"_A1a_","_A1b_"),$A:$H,8,FALSE),"same","DIFF"),"")
A34: npm_A1b_B1b_B2b_C1a | B34: 46272.559 | C34: nodejs | D34: A1b | E34: B1b | F34: B2b | G34: C1a | H34: malicious_resolved | I34: xueting-thesis-event-jianding | J34: 103 | K34: https://registry.npmjs.org/xueting-thesis-event-jianding/-/xueting-thesis-event-jianding-1.0.3.tgz | L34: xueting-thesis-service-fasong | M34: 103 | N34: https://registry.npmjs.org/xueting-thesis-service-fasong/-/xueting-thesis-service-fasong-1.0.3.tgz | O34: automation_process/central_automated_pipeline/artifact_download/npm_A1b_B1b_B2b_C1a | P34: 392d628e1a62a0ac3b0154c32f38e530fc871c0a | Q34: 34116456879 | R34: =C34&"|"&D34&"|"&E34&"|"&F34&"|"&G34 -> nodejs|A1b|B1b|B2b|C1a | S34: =IF(H34="malicious_resolved","M",IF(H34="private_resolved","P",IF(H34="resolution_error","E","-"))) -> M | T34: =IF(G34="C1a",IF(H34=VLOOKUP(SUBSTITUTE(A34,"_C1a","_C1c"),$A:$H,8,FALSE),"same","DIFF"),"") -> same | U34: =IF(AND(C34="nodejs",E34="B1b"),IF(H34=VLOOKUP(SUBSTITUTE(A34,"_B1b_","_B1d_"),$A:$H,8,FALSE),"same","DIFF"),"") -> same | V34: =IF(AND(C34="nodejs",E34="B1c",H34<>"invalid_configuration"),IF(H34=VLOOKUP(SUBSTITUTE(A34,"_B1c_","_B1b_"),$A:$H,8,FALSE),"same","DIFF"),"") | W34: =IF(D34="A1a",IF(H34=VLOOKUP(SUBSTITUTE(A34,"_A1a_","_A1b_"),$A:$H,8,FALSE),"same","DIFF"),"")
A35: npm_A1b_B1b_B2b_C1c | B35: 46272.56 | C35: nodejs | D35: A1b | E35: B1b | F35: B2b | G35: C1c | H35: malicious_resolved | I35: xueting-thesis-event-jianding | J35: 103 | K35: https://registry.npmjs.org/xueting-thesis-event-jianding/-/xueting-thesis-event-jianding-1.0.3.tgz | L35: xueting-thesis-service-fasong | M35: 103 | N35: https://registry.npmjs.org/xueting-thesis-service-fasong/-/xueting-thesis-service-fasong-1.0.3.tgz | O35: automation_process/central_automated_pipeline/artifact_download/npm_A1b_B1b_B2b_C1c | P35: 392d628e1a62a0ac3b0154c32f38e530fc871c0a | Q35: 34116567249 | R35: =C35&"|"&D35&"|"&E35&"|"&F35&"|"&G35 -> nodejs|A1b|B1b|B2b|C1c | S35: =IF(H35="malicious_resolved","M",IF(H35="private_resolved","P",IF(H35="resolution_error","E","-"))) -> M | T35: =IF(G35="C1a",IF(H35=VLOOKUP(SUBSTITUTE(A35,"_C1a","_C1c"),$A:$H,8,FALSE),"same","DIFF"),"") | U35: =IF(AND(C35="nodejs",E35="B1b"),IF(H35=VLOOKUP(SUBSTITUTE(A35,"_B1b_","_B1d_"),$A:$H,8,FALSE),"same","DIFF"),"") -> same | V35: =IF(AND(C35="nodejs",E35="B1c",H35<>"invalid_configuration"),IF(H35=VLOOKUP(SUBSTITUTE(A35,"_B1c_","_B1b_"),$A:$H,8,FALSE),"same","DIFF"),"") | W35: =IF(D35="A1a",IF(H35=VLOOKUP(SUBSTITUTE(A35,"_A1a_","_A1b_"),$A:$H,8,FALSE),"same","DIFF"),"")
A36: npm_A1b_B1b_B2c_C1a | B36: 46272.56 | C36: nodejs | D36: A1b | E36: B1b | F36: B2c | G36: C1a | H36: malicious_resolved | I36: xueting-thesis-event-jianding | J36: 103 | K36: https://registry.npmjs.org/xueting-thesis-event-jianding/-/xueting-thesis-event-jianding-1.0.3.tgz | L36: xueting-thesis-service-fasong | M36: 103 | N36: https://registry.npmjs.org/xueting-thesis-service-fasong/-/xueting-thesis-service-fasong-1.0.3.tgz | O36: automation_process/central_automated_pipeline/artifact_download/npm_A1b_B1b_B2c_C1a | P36: 392d628e1a62a0ac3b0154c32f38e530fc871c0a | Q36: 34116621847 | R36: =C36&"|"&D36&"|"&E36&"|"&F36&"|"&G36 -> nodejs|A1b|B1b|B2c|C1a | S36: =IF(H36="malicious_resolved","M",IF(H36="private_resolved","P",IF(H36="resolution_error","E","-"))) -> M | T36: =IF(G36="C1a",IF(H36=VLOOKUP(SUBSTITUTE(A36,"_C1a","_C1c"),$A:$H,8,FALSE),"same","DIFF"),"") -> same | U36: =IF(AND(C36="nodejs",E36="B1b"),IF(H36=VLOOKUP(SUBSTITUTE(A36,"_B1b_","_B1d_"),$A:$H,8,FALSE),"same","DIFF"),"") -> same | V36: =IF(AND(C36="nodejs",E36="B1c",H36<>"invalid_configuration"),IF(H36=VLOOKUP(SUBSTITUTE(A36,"_B1c_","_B1b_"),$A:$H,8,FALSE),"same","DIFF"),"") | W36: =IF(D36="A1a",IF(H36=VLOOKUP(SUBSTITUTE(A36,"_A1a_","_A1b_"),$A:$H,8,FALSE),"same","DIFF"),"")
A37: npm_A1b_B1b_B2c_C1c | B37: 46272.561 | C37: nodejs | D37: A1b | E37: B1b | F37: B2c | G37: C1c | H37: malicious_resolved | I37: xueting-thesis-event-jianding | J37: 103 | K37: https://registry.npmjs.org/xueting-thesis-event-jianding/-/xueting-thesis-event-jianding-1.0.3.tgz | L37: xueting-thesis-service-fasong | M37: 103 | N37: https://registry.npmjs.org/xueting-thesis-service-fasong/-/xueting-thesis-service-fasong-1.0.3.tgz | O37: automation_process/central_automated_pipeline/artifact_download/npm_A1b_B1b_B2c_C1c | P37: 392d628e1a62a0ac3b0154c32f38e530fc871c0a | Q37: 34116718007 | R37: =C37&"|"&D37&"|"&E37&"|"&F37&"|"&G37 -> nodejs|A1b|B1b|B2c|C1c | S37: =IF(H37="malicious_resolved","M",IF(H37="private_resolved","P",IF(H37="resolution_error","E","-"))) -> M | T37: =IF(G37="C1a",IF(H37=VLOOKUP(SUBSTITUTE(A37,"_C1a","_C1c"),$A:$H,8,FALSE),"same","DIFF"),"") | U37: =IF(AND(C37="nodejs",E37="B1b"),IF(H37=VLOOKUP(SUBSTITUTE(A37,"_B1b_","_B1d_"),$A:$H,8,FALSE),"same","DIFF"),"") -> same | V37: =IF(AND(C37="nodejs",E37="B1c",H37<>"invalid_configuration"),IF(H37=VLOOKUP(SUBSTITUTE(A37,"_B1c_","_B1b_"),$A:$H,8,FALSE),"same","DIFF"),"") | W37: =IF(D37="A1a",IF(H37=VLOOKUP(SUBSTITUTE(A37,"_A1a_","_A1b_"),$A:$H,8,FALSE),"same","DIFF"),"")
A38: npm_A1b_B1c_B2a_C1a | B38: 46272.561 | C38: nodejs | D38: A1b | E38: B1c | F38: B2a | G38: C1a | H38: resolution_error | O38: automation_process/central_automated_pipeline/artifact_download/npm_A1b_B1c_B2a_C1a | P38: 392d628e1a62a0ac3b0154c32f38e530fc871c0a | Q38: 34116770132 | R38: =C38&"|"&D38&"|"&E38&"|"&F38&"|"&G38 -> nodejs|A1b|B1c|B2a|C1a | S38: =IF(H38="malicious_resolved","M",IF(H38="private_resolved","P",IF(H38="resolution_error","E","-"))) -> E | T38: =IF(G38="C1a",IF(H38=VLOOKUP(SUBSTITUTE(A38,"_C1a","_C1c"),$A:$H,8,FALSE),"same","DIFF"),"") -> same | U38: =IF(AND(C38="nodejs",E38="B1b"),IF(H38=VLOOKUP(SUBSTITUTE(A38,"_B1b_","_B1d_"),$A:$H,8,FALSE),"same","DIFF"),"") | V38: =IF(AND(C38="nodejs",E38="B1c",H38<>"invalid_configuration"),IF(H38=VLOOKUP(SUBSTITUTE(A38,"_B1c_","_B1b_"),$A:$H,8,FALSE),"same","DIFF"),"") -> same | W38: =IF(D38="A1a",IF(H38=VLOOKUP(SUBSTITUTE(A38,"_A1a_","_A1b_"),$A:$H,8,FALSE),"same","DIFF"),"")
A39: npm_A1b_B1c_B2a_C1c | B39: 46272.562 | C39: nodejs | D39: A1b | E39: B1c | F39: B2a | G39: C1c | H39: resolution_error | O39: automation_process/central_automated_pipeline/artifact_download/npm_A1b_B1c_B2a_C1c | P39: 392d628e1a62a0ac3b0154c32f38e530fc871c0a | Q39: 34116863329 | R39: =C39&"|"&D39&"|"&E39&"|"&F39&"|"&G39 -> nodejs|A1b|B1c|B2a|C1c | S39: =IF(H39="malicious_resolved","M",IF(H39="private_resolved","P",IF(H39="resolution_error","E","-"))) -> E | T39: =IF(G39="C1a",IF(H39=VLOOKUP(SUBSTITUTE(A39,"_C1a","_C1c"),$A:$H,8,FALSE),"same","DIFF"),"") | U39: =IF(AND(C39="nodejs",E39="B1b"),IF(H39=VLOOKUP(SUBSTITUTE(A39,"_B1b_","_B1d_"),$A:$H,8,FALSE),"same","DIFF"),"") | V39: =IF(AND(C39="nodejs",E39="B1c",H39<>"invalid_configuration"),IF(H39=VLOOKUP(SUBSTITUTE(A39,"_B1c_","_B1b_"),$A:$H,8,FALSE),"same","DIFF"),"") -> same | W39: =IF(D39="A1a",IF(H39=VLOOKUP(SUBSTITUTE(A39,"_A1a_","_A1b_"),$A:$H,8,FALSE),"same","DIFF"),"")
A40: npm_A1b_B1c_B2b_C1a | B40: 46272.563 | C40: nodejs | D40: A1b | E40: B1c | F40: B2b | G40: C1a | H40: malicious_resolved | I40: xueting-thesis-event-jianding | J40: 103 | K40: http://host.docker.internal:8081/repository/npm-public-proxy/xueting-thesis-event-jianding/-/xueting-thesis-event-jianding-1.0.3.tgz | L40: xueting-thesis-service-fasong | M40: 103 | N40: http://host.docker.internal:8081/repository/npm-public-proxy/xueting-thesis-service-fasong/-/xueting-thesis-service-fasong-1.0.3.tgz | O40: automation_process/central_automated_pipeline/artifact_download/npm_A1b_B1c_B2b_C1a | P40: 392d628e1a62a0ac3b0154c32f38e530fc871c0a | Q40: 34116911633 | R40: =C40&"|"&D40&"|"&E40&"|"&F40&"|"&G40 -> nodejs|A1b|B1c|B2b|C1a | S40: =IF(H40="malicious_resolved","M",IF(H40="private_resolved","P",IF(H40="resolution_error","E","-"))) -> M | T40: =IF(G40="C1a",IF(H40=VLOOKUP(SUBSTITUTE(A40,"_C1a","_C1c"),$A:$H,8,FALSE),"same","DIFF"),"") -> same | U40: =IF(AND(C40="nodejs",E40="B1b"),IF(H40=VLOOKUP(SUBSTITUTE(A40,"_B1b_","_B1d_"),$A:$H,8,FALSE),"same","DIFF"),"") | V40: =IF(AND(C40="nodejs",E40="B1c",H40<>"invalid_configuration"),IF(H40=VLOOKUP(SUBSTITUTE(A40,"_B1c_","_B1b_"),$A:$H,8,FALSE),"same","DIFF"),"") -> same | W40: =IF(D40="A1a",IF(H40=VLOOKUP(SUBSTITUTE(A40,"_A1a_","_A1b_"),$A:$H,8,FALSE),"same","DIFF"),"")
...

Sheet FigureC
A1: nodejs
C2: B2a | D2: B2a | E2: B2a | F2: B2b | G2: B2b | H2: B2b | I2: B2c | J2: B2c | K2: B2c
C3: C1a | D3: C1b | E3: C1c | F3: C1a | G3: C1b | H3: C1c | I3: C1a | J3: C1b | K3: C1c
A4: A1a | B4: B1a | C4: =IFERROR(VLOOKUP($A$1&"|"&$A4&"|"&$B4&"|"&C$2&"|"&C$3,'results'!$R:$S,2,FALSE),"?") -> P | D4: =IFERROR(VLOOKUP($A$1&"|"&$A4&"|"&$B4&"|"&D$2&"|"&D$3,'results'!$R:$S,2,FALSE),"?") -> P | E4: =IFERROR(VLOOKUP($A$1&"|"&$A4&"|"&$B4&"|"&E$2&"|"&E$3,'results'!$R:$S,2,FALSE),"?") -> P | F4: =IFERROR(VLOOKUP($A$1&"|"&$A4&"|"&$B4&"|"&F$2&"|"&F$3,'results'!$R:$S,2,FALSE),"?") -> M | G4: =IFERROR(VLOOKUP($A$1&"|"&$A4&"|"&$B4&"|"&G$2&"|"&G$3,'results'!$R:$S,2,FALSE),"?") -> M | H4: =IFERROR(VLOOKUP($A$1&"|"&$A4&"|"&$B4&"|"&H$2&"|"&H$3,'results'!$R:$S,2,FALSE),"?") -> M | I4: =IFERROR(VLOOKUP($A$1&"|"&$A4&"|"&$B4&"|"&I$2&"|"&I$3,'results'!$R:$S,2,FALSE),"?") -> M | J4: =IFERROR(VLOOKUP($A$1&"|"&$A4&"|"&$B4&"|"&J$2&"|"&J$3,'results'!$R:$S,2,FALSE),"?") -> M | K4: =IFERROR(VLOOKUP($A$1&"|"&$A4&"|"&$B4&"|"&K$2&"|"&K$3,'results'!$R:$S,2,FALSE),"?") -> M
A5: A1a | B5: B1b | C5: =IFERROR(VLOOKUP($A$1&"|"&$A5&"|"&$B5&"|"&C$2&"|"&C$3,'results'!$R:$S,2,FALSE),"?") -> E | D5: =IFERROR(VLOOKUP($A$1&"|"&$A5&"|"&$B5&"|"&D$2&"|"&D$3,'results'!$R:$S,2,FALSE),"?") -> E | E5: =IFERROR(VLOOKUP($A$1&"|"&$A5&"|"&$B5&"|"&E$2&"|"&E$3,'results'!$R:$S,2,FALSE),"?") -> E | F5: =IFERROR(VLOOKUP($A$1&"|"&$A5&"|"&$B5&"|"&F$2&"|"&F$3,'results'!$R:$S,2,FALSE),"?") -> M | G5: =IFERROR(VLOOKUP($A$1&"|"&$A5&"|"&$B5&"|"&G$2&"|"&G$3,'results'!$R:$S,2,FALSE),"?") -> M | H5: =IFERROR(VLOOKUP($A$1&"|"&$A5&"|"&$B5&"|"&H$2&"|"&H$3,'results'!$R:$S,2,FALSE),"?") -> M | I5: =IFERROR(VLOOKUP($A$1&"|"&$A5&"|"&$B5&"|"&I$2&"|"&I$3,'results'!$R:$S,2,FALSE),"?") -> M | J5: =IFERROR(VLOOKUP($A$1&"|"&$A5&"|"&$B5&"|"&J$2&"|"&J$3,'results'!$R:$S,2,FALSE),"?") -> M | K5: =IFERROR(VLOOKUP($A$1&"|"&$A5&"|"&$B5&"|"&K$2&"|"&K$3,'results'!$R:$S,2,FALSE),"?") -> M
A6: A1a | B6: B1c | C6: =IFERROR(VLOOKUP($A$1&"|"&$A6&"|"&$B6&"|"&C$2&"|"&C$3,'results'!$R:$S,2,FALSE),"?") -> E | D6: =IFERROR(VLOOKUP($A$1&"|"&$A6&"|"&$B6&"|"&D$2&"|"&D$3,'results'!$R:$S,2,FALSE),"?") -> E | E6: =IFERROR(VLOOKUP($A$1&"|"&$A6&"|"&$B6&"|"&E$2&"|"&E$3,'results'!$R:$S,2,FALSE),"?") -> E | F6: =IFERROR(VLOOKUP($A$1&"|"&$A6&"|"&$B6&"|"&F$2&"|"&F$3,'results'!$R:$S,2,FALSE),"?") -> M | G6: =IFERROR(VLOOKUP($A$1&"|"&$A6&"|"&$B6&"|"&G$2&"|"&G$3,'results'!$R:$S,2,FALSE),"?") -> M | H6: =IFERROR(VLOOKUP($A$1&"|"&$A6&"|"&$B6&"|"&H$2&"|"&H$3,'results'!$R:$S,2,FALSE),"?") -> M | I6: =IFERROR(VLOOKUP($A$1&"|"&$A6&"|"&$B6&"|"&I$2&"|"&I$3,'results'!$R:$S,2,FALSE),"?") -> M | J6: =IFERROR(VLOOKUP($A$1&"|"&$A6&"|"&$B6&"|"&J$2&"|"&J$3,'results'!$R:$S,2,FALSE),"?") -> M | K6: =IFERROR(VLOOKUP($A$1&"|"&$A6&"|"&$B6&"|"&K$2&"|"&K$3,'results'!$R:$S,2,FALSE),"?") -> M
A7: A1a | B7: B1d | C7: =IFERROR(VLOOKUP($A$1&"|"&$A7&"|"&$B7&"|"&C$2&"|"&C$3,'results'!$R:$S,2,FALSE),"?") -> E | D7: =IFERROR(VLOOKUP($A$1&"|"&$A7&"|"&$B7&"|"&D$2&"|"&D$3,'results'!$R:$S,2,FALSE),"?") -> E | E7: =IFERROR(VLOOKUP($A$1&"|"&$A7&"|"&$B7&"|"&E$2&"|"&E$3,'results'!$R:$S,2,FALSE),"?") -> E | F7: =IFERROR(VLOOKUP($A$1&"|"&$A7&"|"&$B7&"|"&F$2&"|"&F$3,'results'!$R:$S,2,FALSE),"?") -> M | G7: =IFERROR(VLOOKUP($A$1&"|"&$A7&"|"&$B7&"|"&G$2&"|"&G$3,'results'!$R:$S,2,FALSE),"?") -> M | H7: =IFERROR(VLOOKUP($A$1&"|"&$A7&"|"&$B7&"|"&H$2&"|"&H$3,'results'!$R:$S,2,FALSE),"?") -> M | I7: =IFERROR(VLOOKUP($A$1&"|"&$A7&"|"&$B7&"|"&I$2&"|"&I$3,'results'!$R:$S,2,FALSE),"?") -> M | J7: =IFERROR(VLOOKUP($A$1&"|"&$A7&"|"&$B7&"|"&J$2&"|"&J$3,'results'!$R:$S,2,FALSE),"?") -> M | K7: =IFERROR(VLOOKUP($A$1&"|"&$A7&"|"&$B7&"|"&K$2&"|"&K$3,'results'!$R:$S,2,FALSE),"?") -> M
A8: A1b | B8: B1a | C8: =IFERROR(VLOOKUP($A$1&"|"&$A8&"|"&$B8&"|"&C$2&"|"&C$3,'results'!$R:$S,2,FALSE),"?") -> P | D8: =IFERROR(VLOOKUP($A$1&"|"&$A8&"|"&$B8&"|"&D$2&"|"&D$3,'results'!$R:$S,2,FALSE),"?") -> P | E8: =IFERROR(VLOOKUP($A$1&"|"&$A8&"|"&$B8&"|"&E$2&"|"&E$3,'results'!$R:$S,2,FALSE),"?") -> P | F8: =IFERROR(VLOOKUP($A$1&"|"&$A8&"|"&$B8&"|"&F$2&"|"&F$3,'results'!$R:$S,2,FALSE),"?") -> M | G8: =IFERROR(VLOOKUP($A$1&"|"&$A8&"|"&$B8&"|"&G$2&"|"&G$3,'results'!$R:$S,2,FALSE),"?") -> M | H8: =IFERROR(VLOOKUP($A$1&"|"&$A8&"|"&$B8&"|"&H$2&"|"&H$3,'results'!$R:$S,2,FALSE),"?") -> M | I8: =IFERROR(VLOOKUP($A$1&"|"&$A8&"|"&$B8&"|"&I$2&"|"&I$3,'results'!$R:$S,2,FALSE),"?") -> M | J8: =IFERROR(VLOOKUP($A$1&"|"&$A8&"|"&$B8&"|"&J$2&"|"&J$3,'results'!$R:$S,2,FALSE),"?") -> M | K8: =IFERROR(VLOOKUP($A$1&"|"&$A8&"|"&$B8&"|"&K$2&"|"&K$3,'results'!$R:$S,2,FALSE),"?") -> M
A9: A1b | B9: B1b | C9: =IFERROR(VLOOKUP($A$1&"|"&$A9&"|"&$B9&"|"&C$2&"|"&C$3,'results'!$R:$S,2,FALSE),"?") -> E | D9: =IFERROR(VLOOKUP($A$1&"|"&$A9&"|"&$B9&"|"&D$2&"|"&D$3,'results'!$R:$S,2,FALSE),"?") -> E | E9: =IFERROR(VLOOKUP($A$1&"|"&$A9&"|"&$B9&"|"&E$2&"|"&E$3,'results'!$R:$S,2,FALSE),"?") -> E | F9: =IFERROR(VLOOKUP($A$1&"|"&$A9&"|"&$B9&"|"&F$2&"|"&F$3,'results'!$R:$S,2,FALSE),"?") -> M | G9: =IFERROR(VLOOKUP($A$1&"|"&$A9&"|"&$B9&"|"&G$2&"|"&G$3,'results'!$R:$S,2,FALSE),"?") -> M | H9: =IFERROR(VLOOKUP($A$1&"|"&$A9&"|"&$B9&"|"&H$2&"|"&H$3,'results'!$R:$S,2,FALSE),"?") -> M | I9: =IFERROR(VLOOKUP($A$1&"|"&$A9&"|"&$B9&"|"&I$2&"|"&I$3,'results'!$R:$S,2,FALSE),"?") -> M | J9: =IFERROR(VLOOKUP($A$1&"|"&$A9&"|"&$B9&"|"&J$2&"|"&J$3,'results'!$R:$S,2,FALSE),"?") -> M | K9: =IFERROR(VLOOKUP($A$1&"|"&$A9&"|"&$B9&"|"&K$2&"|"&K$3,'results'!$R:$S,2,FALSE),"?") -> M
A10: A1b | B10: B1c | C10: =IFERROR(VLOOKUP($A$1&"|"&$A10&"|"&$B10&"|"&C$2&"|"&C$3,'results'!$R:$S,2,FALSE),"?") -> E | D10: =IFERROR(VLOOKUP($A$1&"|"&$A10&"|"&$B10&"|"&D$2&"|"&D$3,'results'!$R:$S,2,FALSE),"?") -> E | E10: =IFERROR(VLOOKUP($A$1&"|"&$A10&"|"&$B10&"|"&E$2&"|"&E$3,'results'!$R:$S,2,FALSE),"?") -> E | F10: =IFERROR(VLOOKUP($A$1&"|"&$A10&"|"&$B10&"|"&F$2&"|"&F$3,'results'!$R:$S,2,FALSE),"?") -> M | G10: =IFERROR(VLOOKUP($A$1&"|"&$A10&"|"&$B10&"|"&G$2&"|"&G$3,'results'!$R:$S,2,FALSE),"?") -> M | H10: =IFERROR(VLOOKUP($A$1&"|"&$A10&"|"&$B10&"|"&H$2&"|"&H$3,'results'!$R:$S,2,FALSE),"?") -> M | I10: =IFERROR(VLOOKUP($A$1&"|"&$A10&"|"&$B10&"|"&I$2&"|"&I$3,'results'!$R:$S,2,FALSE),"?") -> M | J10: =IFERROR(VLOOKUP($A$1&"|"&$A10&"|"&$B10&"|"&J$2&"|"&J$3,'results'!$R:$S,2,FALSE),"?") -> M | K10: =IFERROR(VLOOKUP($A$1&"|"&$A10&"|"&$B10&"|"&K$2&"|"&K$3,'results'!$R:$S,2,FALSE),"?") -> M
A11: A1b | B11: B1d | C11: =IFERROR(VLOOKUP($A$1&"|"&$A11&"|"&$B11&"|"&C$2&"|"&C$3,'results'!$R:$S,2,FALSE),"?") -> E | D11: =IFERROR(VLOOKUP($A$1&"|"&$A11&"|"&$B11&"|"&D$2&"|"&D$3,'results'!$R:$S,2,FALSE),"?") -> E | E11: =IFERROR(VLOOKUP($A$1&"|"&$A11&"|"&$B11&"|"&E$2&"|"&E$3,'results'!$R:$S,2,FALSE),"?") -> E | F11: =IFERROR(VLOOKUP($A$1&"|"&$A11&"|"&$B11&"|"&F$2&"|"&F$3,'results'!$R:$S,2,FALSE),"?") -> M | G11: =IFERROR(VLOOKUP($A$1&"|"&$A11&"|"&$B11&"|"&G$2&"|"&G$3,'results'!$R:$S,2,FALSE),"?") -> M | H11: =IFERROR(VLOOKUP($A$1&"|"&$A11&"|"&$B11&"|"&H$2&"|"&H$3,'results'!$R:$S,2,FALSE),"?") -> M | I11: =IFERROR(VLOOKUP($A$1&"|"&$A11&"|"&$B11&"|"&I$2&"|"&I$3,'results'!$R:$S,2,FALSE),"?") -> M | J11: =IFERROR(VLOOKUP($A$1&"|"&$A11&"|"&$B11&"|"&J$2&"|"&J$3,'results'!$R:$S,2,FALSE),"?") -> M | K11: =IFERROR(VLOOKUP($A$1&"|"&$A11&"|"&$B11&"|"&K$2&"|"&K$3,'results'!$R:$S,2,FALSE),"?") -> M
A12: A2 | B12: B1a | C12: =IFERROR(VLOOKUP($A$1&"|"&$A12&"|"&$B12&"|"&C$2&"|"&C$3,'results'!$R:$S,2,FALSE),"?") -> E | D12: =IFERROR(VLOOKUP($A$1&"|"&$A12&"|"&$B12&"|"&D$2&"|"&D$3,'results'!$R:$S,2,FALSE),"?") -> P | E12: =IFERROR(VLOOKUP($A$1&"|"&$A12&"|"&$B12&"|"&E$2&"|"&E$3,'results'!$R:$S,2,FALSE),"?") -> E | F12: =IFERROR(VLOOKUP($A$1&"|"&$A12&"|"&$B12&"|"&F$2&"|"&F$3,'results'!$R:$S,2,FALSE),"?") -> E | G12: =IFERROR(VLOOKUP($A$1&"|"&$A12&"|"&$B12&"|"&G$2&"|"&G$3,'results'!$R:$S,2,FALSE),"?") -> P | H12: =IFERROR(VLOOKUP($A$1&"|"&$A12&"|"&$B12&"|"&H$2&"|"&H$3,'results'!$R:$S,2,FALSE),"?") -> E | I12: =IFERROR(VLOOKUP($A$1&"|"&$A12&"|"&$B12&"|"&I$2&"|"&I$3,'results'!$R:$S,2,FALSE),"?") -> E | J12: =IFERROR(VLOOKUP($A$1&"|"&$A12&"|"&$B12&"|"&J$2&"|"&J$3,'results'!$R:$S,2,FALSE),"?") -> P | K12: =IFERROR(VLOOKUP($A$1&"|"&$A12&"|"&$B12&"|"&K$2&"|"&K$3,'results'!$R:$S,2,FALSE),"?") -> E
A13: A2 | B13: B1b | C13: =IFERROR(VLOOKUP($A$1&"|"&$A13&"|"&$B13&"|"&C$2&"|"&C$3,'results'!$R:$S,2,FALSE),"?") -> E | D13: =IFERROR(VLOOKUP($A$1&"|"&$A13&"|"&$B13&"|"&D$2&"|"&D$3,'results'!$R:$S,2,FALSE),"?") -> E | E13: =IFERROR(VLOOKUP($A$1&"|"&$A13&"|"&$B13&"|"&E$2&"|"&E$3,'results'!$R:$S,2,FALSE),"?") -> E | F13: =IFERROR(VLOOKUP($A$1&"|"&$A13&"|"&$B13&"|"&F$2&"|"&F$3,'results'!$R:$S,2,FALSE),"?") -> M | G13: =IFERROR(VLOOKUP($A$1&"|"&$A13&"|"&$B13&"|"&G$2&"|"&G$3,'results'!$R:$S,2,FALSE),"?") -> M | H13: =IFERROR(VLOOKUP($A$1&"|"&$A13&"|"&$B13&"|"&H$2&"|"&H$3,'results'!$R:$S,2,FALSE),"?") -> M | I13: =IFERROR(VLOOKUP($A$1&"|"&$A13&"|"&$B13&"|"&I$2&"|"&I$3,'results'!$R:$S,2,FALSE),"?") -> M | J13: =IFERROR(VLOOKUP($A$1&"|"&$A13&"|"&$B13&"|"&J$2&"|"&J$3,'results'!$R:$S,2,FALSE),"?") -> M | K13: =IFERROR(VLOOKUP($A$1&"|"&$A13&"|"&$B13&"|"&K$2&"|"&K$3,'results'!$R:$S,2,FALSE),"?") -> M
A14: A2 | B14: B1c | C14: =IFERROR(VLOOKUP($A$1&"|"&$A14&"|"&$B14&"|"&C$2&"|"&C$3,'results'!$R:$S,2,FALSE),"?") -> E | D14: =IFERROR(VLOOKUP($A$1&"|"&$A14&"|"&$B14&"|"&D$2&"|"&D$3,'results'!$R:$S,2,FALSE),"?") -> E | E14: =IFERROR(VLOOKUP($A$1&"|"&$A14&"|"&$B14&"|"&E$2&"|"&E$3,'results'!$R:$S,2,FALSE),"?") -> E | F14: =IFERROR(VLOOKUP($A$1&"|"&$A14&"|"&$B14&"|"&F$2&"|"&F$3,'results'!$R:$S,2,FALSE),"?") -> M | G14: =IFERROR(VLOOKUP($A$1&"|"&$A14&"|"&$B14&"|"&G$2&"|"&G$3,'results'!$R:$S,2,FALSE),"?") -> M | H14: =IFERROR(VLOOKUP($A$1&"|"&$A14&"|"&$B14&"|"&H$2&"|"&H$3,'results'!$R:$S,2,FALSE),"?") -> M | I14: =IFERROR(VLOOKUP($A$1&"|"&$A14&"|"&$B14&"|"&I$2&"|"&I$3,'results'!$R:$S,2,FALSE),"?") -> M | J14: =IFERROR(VLOOKUP($A$1&"|"&$A14&"|"&$B14&"|"&J$2&"|"&J$3,'results'!$R:$S,2,FALSE),"?") -> M | K14: =IFERROR(VLOOKUP($A$1&"|"&$A14&"|"&$B14&"|"&K$2&"|"&K$3,'results'!$R:$S,2,FALSE),"?") -> M
A15: A2 | B15: B1d | C15: =IFERROR(VLOOKUP($A$1&"|"&$A15&"|"&$B15&"|"&C$2&"|"&C$3,'results'!$R:$S,2,FALSE),"?") -> E | D15: =IFERROR(VLOOKUP($A$1&"|"&$A15&"|"&$B15&"|"&D$2&"|"&D$3,'results'!$R:$S,2,FALSE),"?") -> E | E15: =IFERROR(VLOOKUP($A$1&"|"&$A15&"|"&$B15&"|"&E$2&"|"&E$3,'results'!$R:$S,2,FALSE),"?") -> E | F15: =IFERROR(VLOOKUP($A$1&"|"&$A15&"|"&$B15&"|"&F$2&"|"&F$3,'results'!$R:$S,2,FALSE),"?") -> M | G15: =IFERROR(VLOOKUP($A$1&"|"&$A15&"|"&$B15&"|"&G$2&"|"&G$3,'results'!$R:$S,2,FALSE),"?") -> M | H15: =IFERROR(VLOOKUP($A$1&"|"&$A15&"|"&$B15&"|"&H$2&"|"&H$3,'results'!$R:$S,2,FALSE),"?") -> M | I15: =IFERROR(VLOOKUP($A$1&"|"&$A15&"|"&$B15&"|"&I$2&"|"&I$3,'results'!$R:$S,2,FALSE),"?") -> M | J15: =IFERROR(VLOOKUP($A$1&"|"&$A15&"|"&$B15&"|"&J$2&"|"&J$3,'results'!$R:$S,2,FALSE),"?") -> M | K15: =IFERROR(VLOOKUP($A$1&"|"&$A15&"|"&$B15&"|"&K$2&"|"&K$3,'results'!$R:$S,2,FALSE),"?") -> M
... A19: A3 | B19: B1d | C19: =IFERROR(VLOOKUP($A$1&"|"&$A19&"|"&$B19&"|"&C$2&"|"&C$3,'results'!$R:$S,2,FALSE),"?") -> E | D19: =IFERROR(VLOOKUP($A$1&"|"&$A19&"|"&$B19&"|"&D$2&"|"&D$3,'results'!$R:$S,2,FALSE),"?") -> E | E19: =IFERROR(VLOOKUP($A$1&"|"&$A19&"|"&$B19&"|"&E$2&"|"&E$3,'results'!$R:$S,2,FALSE),"?") -> E | F19: =IFERROR(VLOOKUP($A$1&"|"&$A19&"|"&$B19&"|"&F$2&"|"&F$3,'results'!$R:$S,2,FALSE),"?") -> M | G19: =IFERROR(VLOOKUP($A$1&"|"&$A19&"|"&$B19&"|"&G$2&"|"&G$3,'results'!$R:$S,2,FALSE),"?") -> M | H19: =IFERROR(VLOOKUP($A$1&"|"&$A19&"|"&$B19&"|"&H$2&"|"&H$3,'results'!$R:$S,2,FALSE),"?") -> M | I19: =IFERROR(VLOOKUP($A$1&"|"&$A19&"|"&$B19&"|"&I$2&"|"&I$3,'results'!$R:$S,2,FALSE),"?") -> M | J19: =IFERROR(VLOOKUP($A$1&"|"&$A19&"|"&$B19&"|"&J$2&"|"&J$3,'results'!$R:$S,2,FALSE),"?") -> M | K19: =IFERROR(VLOOKUP($A$1&"|"&$A19&"|"&$B19&"|"&K$2&"|"&K$3,'results'!$R:$S,2,FALSE),"?") -> M
A22: python
C23: B2a | D23: B2a | E23: B2a | F23: B2b | G23: B2b | H23: B2b | I23: B2c | J23: B2c | K23: B2c
C24: C1a | D24: C1b | E24: C1c | F24: C1a | G24: C1b | H24: C1c | I24: C1a | J24: C1b | K24: C1c
